Workbook

Sheet RA Information
A2: SEV CRITICAL SPARES RISK ASSESSMENT – EXAMPLE VESSEL
A4: RISK MANAGEMENT INFORMATION
A6: Risk Assessment ID: | B6: SM RA-SEV/EXV1/001 | C6: Vessel: | D6: Example Vessel (Example Vessel Type)
A7: Vessel Provider: | B7: Example Provider Ltd | C7: Operating Region: | D7: West Africa (Gulf of Guinea)
A8: Activity Description: | B8: Assessment of critical equipment spare parts availability and associated operational risk for Example Vessel operating as a Security Escort Vessel (SEV) in the West Africa region. This assessment identifies equipment failure scenarios, evaluates the operational and security impact, and verifies that adequate critical spares are maintained onboard to support continuous vessel operations.
A9: Assessed by: | B9: Group Compliance Director | C9: Assessment Date: | D9: March 2026
A10: Contributors: | B10: [TO BE COMPLETED BY PROJECT TEAM] | C10: Review Date: | D10: [TO BE COMPLETED]
A11: Approved by: | B11: Group Compliance Director | C11: Next Review: | D11: 46082
A13: RESPONSIBLE PERSONS
A14: Role: | B14: WAF Compliance Operations Manager | C14: Responsibility: | D14: Overall responsibility for ensuring vessel readiness and spares compliance for Seagull Maritime
A15: Role: | B15: Chief Engineer / Electrician | C15: Responsibility: | D15: Day-to-day inspection, testing, and inventory management of all engineering and electrical spares
A16: Role: | B16: Ship Security Officer (SSO) | C16: Responsibility: | D16: Responsibility for security equipment spares and operational readiness
A17: Role: | B17: Master | C17: Responsibility: | D17: Overall vessel safety and ensuring critical equipment is functional and spares are available
A19: COMMUNICATION & CONSULTATION / MONITORING & REVIEW
A20: This risk assessment must be shared with the Chief Engineer and all responsible officers. Any changes to spares availability must be reported to the Operations Manager immediately. Critical shortfalls identified must trigger a procurement request before the vessel deploys on task.
A21: This assessment must be reviewed: (a) quarterly during normal operations, (b) after any equipment failure incident, (c) before deployment on a new client contract, and (d) when the vessel inventory report is updated by the Chief Engineer.
A22: Source document: Critical Equipment Parts Inventory – Example Vessel, dated February 2026, signed by Captain and Chief Engineer, provided by Example Provider Ltd.

Sheet Methodology
A2: RISK ASSESSMENT METHODOLOGY
B4: Likelihood x Consequence = Risk Rating
B6: Likelihood | D6: x | E6: Consequence
B7: 1 | C7: Rare | E7: 1 | F7: Minor inconvenience
B8: 2 | C8: Unlikely | E8: 2 | F8: Reduced capability
B9: 3 | C9: Possible | E9: 3 | F9: Mission degradation
B10: 4 | C10: Likely | E10: 4 | F10: Mission failure
B11: 5 | C11: Almost Certain | E11: 5 | F11: Loss of life / vessel
B14: Risk Rating = Likelihood x Consequence (pre-controls)
B15: Residual Risk = Risk after spare parts and controls are verified onboard
A17: Risk Level Key:
B18: 1–6 | C18: Low | D18: Acceptable risk. Monitor through routine inspection schedule.
B19: 8–12 | C19: Medium | D19: Tolerable with controls in place. Ensure spares are maintained and inspected.
B20: 15–25 | C20: High | D20: Unacceptable without mitigation. Vessel must not deploy until spares shortfall is resolved.

Sheet SEV Critical Spares Register
A2: SEV CRITICAL SPARES REGISTER
A3: Vessel: | B3: Example Vessel | E3: Provider: | F3: Example Provider Ltd | I3: Inventory Date: | J3: February 2026 | M3: Document Ref: | N3: SM RA-SEV/EXV1/001
A5: System Category | B5: Equipment / Spare Part | C5: Failure Scenario | D5: Operational / Security Impact | E5: Likelihood (1-5) | F5: Consequence (1-5) | G5: Risk Rating (L x C) | H5: Risk Level | I5: Existing Controls | J5: Required Critical Spares | K5: Required Quantity | L5: Quantity on Board | M5: Responsible Officer | N5: Inspection / Test Frequency | O5: Residual Risk | P5: Remarks
A6: Propulsion | B6: Main Engine | C6: Engine failure | D6: Loss of escort and evasive capability | E6: 3 | F6: 5 | G6: =E6*F6 -> 15 | H6: =IF(G6="","",IF(G6<=6,"Low",IF(G6<=12,"Medium","High"))) -> High | I6: PMS, redundancy | J6: Filters lub oil | K6: 4 pcs | L6: 4 pcs | M6: Chief Engineer | N6: Daily / Weekly | O6: Medium
J7: filter for fuel | K7: 12 pcs | L7: 12 pcs
J8: breather | K8: nil | L8: nil
J9: valve cover | K9: 7 pcs | L9: 7 pcs
J10: separ filter | K10: 6 pcs | L10: 6 pcs
J11: zinc anodes | K11: 24 pcs | L11: 24 pcs
J12: exhaust manifold | K12: 8 pcs | L12: 8 pcs
A13: Propulsion | B13: Fuel / Water Pump | C13: Pump seizure | D13: Total loss of propulsion | E13: 3 | F13: 5 | G13: =E13*F13 -> 15 | H13: =IF(G13="","",IF(G13<=6,"Low",IF(G13<=12,"Medium","High"))) -> High | I13: Planned maintenance | J13: Spare SUBMERSIBLE PUMP | K13: 1 pcs | L13: 1 pcs | M13: Chief Engineer | N13: Weekly | O13: Medium
A14: Gearbox system | B14: Gear Box | C14: gearbox failure | D14: loss of propulsion control | E14: 3 | F14: 5 | G14: =E14*F14 -> 15 | H14: =IF(G14="","",IF(G14<=6,"Low",IF(G14<=12,"Medium","High"))) -> High | I14: Planned maintenance | J14: Gearbox filter | K14: 7 pcs | L14: 7 pcs | M14: Chief Engineer | N14: Weekly | O14: Medium
J15: seals | K15: 1 pack | L15: 1 pack
A16: Emergency steering | B16: system push solonoid | C16: emergency steering | D16: loss of vessel heading control | E16: 3 | F16: 5 | G16: =E16*F16 -> 15 | H16: =IF(G16="","",IF(G16<=6,"Low",IF(G16<=12,"Medium","High"))) -> High | I16: Planned maintenance | J16: spare push solonoid | K16: 2pcs | L16: 2pcs | M16: Chief Engineer | N16: Weekly | O16: Medium
A17: Propulsion | B17: Steering Gear | C17: Hydraulic failure | D17: Loss of vessel control | E17: 2 | F17: 5 | G17: =E17*F17 -> 10 | H17: =IF(G17="","",IF(G17<=6,"Low",IF(G17<=12,"Medium","High"))) -> Medium | I17: Redundant hydraulics | J17: Hoses | K17: 2 pcs | L17: 2 pcs | M17: Chief Engineer | N17: Weekly | O17: Low
J18: Seals | K18: 4pcs | L18: 4pcs
J19: Fluid | K19: 100 ltrs | L19: 100 ltrs
A20: Ship Auxilliary (generator) and Alternators | B20: Generator Set | C20: Generator failure | D20: Loss of power to sensors/comms | E20: 3 | F20: 5 | G20: =E20*F20 -> 15 | H20: =IF(G20="","",IF(G20<=6,"Low",IF(G20<=12,"Medium","High"))) -> High | I20: Dual gensets | J20: Separ Filters | K20: 06 pcs | L20: 06 pcs | M20: Chief Engineer/Electrician | N20: Daily | O20: Medium
I21: Planned maintenance | J21: fuel filter | K21: 8 pcs | L21: 8 pcs
J22: lub oil filter | K22: 6 pcs | L22: 6 pcs
J23: air filter in an out | K23: 3 pcs In / 4 pcs out | L23: 3 pcs In / 4 pcs out
J24: breather | K24: 6 pcs | L24: 6 pcs
J25: seal pack | K25: 2 pcs | L25: 2 pcs
J26: valve seal cover | K26: 2 pcs | L26: 2 pcs
J27: fuel lifting pump | K27: 1 pcs | L27: 1 pcs
J28: AVR | K28: 1 pcs | L28: 1 pcs
A29: Electrical | B29: Batteries | C29: Battery failure | D29: No start / blackout | E29: 3 | F29: 4 | G29: =E29*F29 -> 12 | H29: =IF(G29="","",IF(G29<=6,"Low",IF(G29<=12,"Medium","High"))) -> Medium | I29: Routine testing/battery log | J29: Spare batteries | K29: 1pcs x 200amps / 12v | L29: 1pcs x 200amps / 12v | M29: Chief Engineer/Electrician | N29: Weekly | O29: Low
A30: Electrical | B30: breakers | C30: Breaker failure | D30: Partial blackout | E30: 2 | F30: 4 | G30: =E30*F30 -> 8 | H30: =IF(G30="","",IF(G30<=6,"Low",IF(G30<=12,"Medium","High"))) -> Medium | I30: Thermal checks | J30: Breaker 1C 60N 4P C16 | K30: 1 pcs | L30: 1 pcs | M30: Chief Engineer/Electrician | N30: Monthly | O30: Low
J31: Breaker 4P C32 | K31: 1 pcs | L31: 1 pcs
J32: Breaker 1C 60N 3P C16 | K32: 1 pcs | L32: 1 pcs
J33: Breaker 1CN60N 3P C10 | K33: 1 pcs | L33: 1 pcs
J34: Breaker 1CN60N 3P C32 | K34: 1 pcs | L34: 1 pcs
J35: Breaker 2P 2A C60N-C | K35: 1 pcs | L35: 1 pcs
J36: Breaker 1C 60N 2P 400V 50HZ AC/DC 1P20 | K36: 1 pcs | L36: 1 pcs
A37: Electrical battery chargers | B37: volt charger | C37: charger failure | D37: Partial blackout | E37: 2 | F37: 4 | G37: =E37*F37 -> 8 | H37: =IF(G37="","",IF(G37<=6,"Low",IF(G37<=12,"Medium","High"))) -> Medium | I37: status periodic checks/ logging | J37: spare volt master charger | K37: 1 pcs | L37: 1 pcs | M37: Chief Engineer/Electrician | N37: daily | O37: Low
A38: Electrical Relays | B38: RELAYS | C38: Breaker failure | D38: Partial equipment failure | E38: 2 | F38: 4 | G38: =E38*F38 -> 8 | H38: =IF(G38="","",IF(G38<=6,"Low",IF(G38<=12,"Medium","High"))) -> Medium | I38: routine checks | J38: Socket relay clamp | K38: 1 pcs | L38: 1 pcs | M38: Chief Engineer/Electrician | N38: daily | O38: Low
J39: Base relay RXM-4A/4G | K39: 1 pcs | L39: 1 pcs
J40: Relay zelio RXM 2C/O-230VAC MINIATURE PLUG IN RELAY | K40: 1 pcs | L40: 1 pcs
J41: mini relay 12A 2W VDC | K41: 1 pcs | L41: 1 pcs | M41: Chief Engineer/Electrician
A42: Air-Condition system | B42: Air condition system | C42: compressor failure | D42: Partial equipment failure | E42: 2 | F42: 4 | G42: =E42*F42 -> 8 | H42: =IF(G42="","",IF(G42<=6,"Low",IF(G42<=12,"Medium","High"))) -> Medium | I42: routine checks | J42: compressor pressure witch | K42: 6 pcs | L42: 6 pcs | M42: Chief Engineer/Electrician | N42: daily | O42: Low
...

Sheet Risk Dashboard
A2: RISK DASHBOARD
B4: Vessel: | C4: Example Vessel | D4: Document Ref: | E4: SM RA-SEV/EXV1/001 | F4: Date: | G4: March 2026
B6: RISK SUMMARY
B7: Metric | C7: Count
B8: Total Risk Items Assessed | C8: =COUNTIF('SEV Critical Spares Register'!G6:G85,">0") -> 27
B9: High Risk Items | C9: =COUNTIF('SEV Critical Spares Register'!H6:H85,"High") -> 6
B10: Medium Risk Items | C10: =COUNTIF('SEV Critical Spares Register'!H6:H85,"Medium") -> 19
B11: Low Risk Items | C11: =COUNTIF('SEV Critical Spares Register'!H6:H85,"Low") -> 2
B12: Average Risk Rating | C12: =IFERROR(AVERAGE('SEV Critical Spares Register'!G6:G85),"") -> 10.740741
B13: Highest Risk Rating | C13: =MAX('SEV Critical Spares Register'!G6:G85) -> 15
B16: RISK BY SYSTEM CATEGORY
B17: System Category | C17: Items | D17: Avg Risk Rating | E17: Max Risk Rating
B18: Propulsion | C18: =COUNTIFS('SEV Critical Spares Register'!A6:A85,"*Propulsion*",'SEV Critical Spares Register'!G6:G85,"<>") -> 3 | D18: =IFERROR(AVERAGEIFS('SEV Critical Spares Register'!G6:G85,'SEV Critical Spares Register'!A6:A85,"*Propulsion*"),"") -> 13.333333 | E18: =IFERROR(_xludf.maxifs('SEV Critical Spares Register'!G6:G85,'SEV Critical Spares Register'!A6:A85,"*Propulsion*"),"")
B19: Gearbox | C19: =COUNTIFS('SEV Critical Spares Register'!A6:A85,"*Gearbox*",'SEV Critical Spares Register'!G6:G85,"<>") -> 1 | D19: =IFERROR(AVERAGEIFS('SEV Critical Spares Register'!G6:G85,'SEV Critical Spares Register'!A6:A85,"*Gearbox*"),"") -> 15 | E19: =IFERROR(_xludf.maxifs('SEV Critical Spares Register'!G6:G85,'SEV Critical Spares Register'!A6:A85,"*Gearbox*"),"")
B20: Emergency steering | C20: =COUNTIFS('SEV Critical Spares Register'!A6:A85,"*Emergency steering*",'SEV Critical Spares Register'!G6:G85,"<>") -> 1 | D20: =IFERROR(AVERAGEIFS('SEV Critical Spares Register'!G6:G85,'SEV Critical Spares Register'!A6:A85,"*Emergency steering*"),"") -> 15 | E20: =IFERROR(_xludf.maxifs('SEV Critical Spares Register'!G6:G85,'SEV Critical Spares Register'!A6:A85,"*Emergency steering*"),"")
B21: Electrical | C21: =COUNTIFS('SEV Critical Spares Register'!A6:A85,"*Electrical*",'SEV Critical Spares Register'!G6:G85,"<>") -> 5 | D21: =IFERROR(AVERAGEIFS('SEV Critical Spares Register'!G6:G85,'SEV Critical Spares Register'!A6:A85,"*Electrical*"),"") -> 8.8 | E21: =IFERROR(_xludf.maxifs('SEV Critical Spares Register'!G6:G85,'SEV Critical Spares Register'!A6:A85,"*Electrical*"),"")
B22: Air-Condition | C22: =COUNTIFS('SEV Critical Spares Register'!A6:A85,"*Air-Condition*",'SEV Critical Spares Register'!G6:G85,"<>") -> 1 | D22: =IFERROR(AVERAGEIFS('SEV Critical Spares Register'!G6:G85,'SEV Critical Spares Register'!A6:A85,"*Air-Condition*"),"") -> 8 | E22: =IFERROR(_xludf.maxifs('SEV Critical Spares Register'!G6:G85,'SEV Critical Spares Register'!A6:A85,"*Air-Condition*"),"")
B23: Navigation | C23: =COUNTIFS('SEV Critical Spares Register'!A6:A85,"*Navigation*",'SEV Critical Spares Register'!G6:G85,"<>") -> 5 | D23: =IFERROR(AVERAGEIFS('SEV Critical Spares Register'!G6:G85,'SEV Critical Spares Register'!A6:A85,"*Navigation*"),"") -> 10.4 | E23: =IFERROR(_xludf.maxifs('SEV Critical Spares Register'!G6:G85,'SEV Critical Spares Register'!A6:A85,"*Navigation*"),"")
B24: Communications | C24: =COUNTIFS('SEV Critical Spares Register'!A6:A85,"*Communications*",'SEV Critical Spares Register'!G6:G85,"<>") -> 3 | D24: =IFERROR(AVERAGEIFS('SEV Critical Spares Register'!G6:G85,'SEV Critical Spares Register'!A6:A85,"*Communications*"),"") -> 9.6666667 | E24: =IFERROR(_xludf.maxifs('SEV Critical Spares Register'!G6:G85,'SEV Critical Spares Register'!A6:A85,"*Communications*"),"")
B25: Security | C25: =COUNTIFS('SEV Critical Spares Register'!A6:A85,"*Security*",'SEV Critical Spares Register'!G6:G85,"<>") -> 3 | D25: =IFERROR(AVERAGEIFS('SEV Critical Spares Register'!G6:G85,'SEV Critical Spares Register'!A6:A85,"*Security*"),"") -> 9.3333333 | E25: =IFERROR(_xludf.maxifs('SEV Critical Spares Register'!G6:G85,'SEV Critical Spares Register'!A6:A85,"*Security*"),"")
B26: Safety | C26: =COUNTIFS('SEV Critical Spares Register'!A6:A85,"*Safety*",'SEV Critical Spares Register'!G6:G85,"<>") -> 4 | D26: =IFERROR(AVERAGEIFS('SEV Critical Spares Register'!G6:G85,'SEV Critical Spares Register'!A6:A85,"*Safety*"),"") -> 11 | E26: =IFERROR(_xludf.maxifs('SEV Critical Spares Register'!G6:G85,'SEV Critical Spares Register'!A6:A85,"*Safety*"),"")
B29: SPARES COMPLIANCE STATUS
B30: Metric | C30: Count
B31: Total Spare Part Lines | C31: =COUNTA('SEV Critical Spares Register'!J6:J85)-COUNTBLANK('SEV Critical Spares Register'!J6:J85) -> 80
B32: Lines Showing "NIL" Stock | C32: =COUNTIF('SEV Critical Spares Register'!L6:L85,"*nil*")+COUNTIF('SEV Critical Spares Register'!L6:L85,"*NIL*") -> 6
