Workbook

Sheet Dashboard
C1: Seagull Maritime — Document Register Dashboard
C2: SM/INT/REG/001 | Version 2.0 | 23 March 2026
B4: DOCUMENT SUMMARY
B5: Total Documents | C5: =C6+C7+C8+C9+C10+C11+C12+C13 | E5: BY SYSTEM
B6: Policies | C6: =COUNTA(Policies!A5:A500) | E6: SEC — Security | F6: =COUNTIF(Policies!C5:C500,"SEC")+COUNTIF('Procedures & SOPs'!C5:C500,"SEC")+COUNTIF('Risk Assessments'!C5:C500,"SEC")+COUNTIF('Registers & Trackers'!C5:C500,"SEC")+COUNTIF('Reports & Position Papers'!C5:C500,"SEC")+COUNTIF('Forms & Templates'!C5:C500,"SEC")+COUNTIF('HR Documents'!C5:C500,"SEC")+COUNTIF('General Documents'!C5:C500,"SEC")
B7: Procedures & SOPs | C7: =COUNTA('Procedures & SOPs'!A5:A500) | E7: QMS — Quality | F7: =COUNTIF(Policies!C5:C500,"QMS")+COUNTIF('Procedures & SOPs'!C5:C500,"QMS")+COUNTIF('Risk Assessments'!C5:C500,"QMS")+COUNTIF('Registers & Trackers'!C5:C500,"QMS")+COUNTIF('Reports & Position Papers'!C5:C500,"QMS")+COUNTIF('Forms & Templates'!C5:C500,"QMS")+COUNTIF('HR Documents'!C5:C500,"QMS")+COUNTIF('General Documents'!C5:C500,"QMS")
B8: Risk Assessments | C8: =COUNTA('Risk Assessments'!A5:A500) | E8: HSE — Health & Safety | F8: =COUNTIF(Policies!C5:C500,"HSE")+COUNTIF('Procedures & SOPs'!C5:C500,"HSE")+COUNTIF('Risk Assessments'!C5:C500,"HSE")+COUNTIF('Registers & Trackers'!C5:C500,"HSE")+COUNTIF('Reports & Position Papers'!C5:C500,"HSE")+COUNTIF('Forms & Templates'!C5:C500,"HSE")+COUNTIF('HR Documents'!C5:C500,"HSE")+COUNTIF('General Documents'!C5:C500,"HSE")
B9: Registers & Trackers | C9: =COUNTA('Registers & Trackers'!A5:A500) | E9: INT — Integrated | F9: =COUNTIF(Policies!C5:C500,"INT")+COUNTIF('Procedures & SOPs'!C5:C500,"INT")+COUNTIF('Risk Assessments'!C5:C500,"INT")+COUNTIF('Registers & Trackers'!C5:C500,"INT")+COUNTIF('Reports & Position Papers'!C5:C500,"INT")+COUNTIF('Forms & Templates'!C5:C500,"INT")+COUNTIF('HR Documents'!C5:C500,"INT")+COUNTIF('General Documents'!C5:C500,"INT")
B10: Reports & Position Papers | C10: =COUNTA('Reports & Position Papers'!A5:A500) | E10: OPS — Operational | F10: =COUNTIF(Policies!C5:C500,"OPS")+COUNTIF('Procedures & SOPs'!C5:C500,"OPS")+COUNTIF('Risk Assessments'!C5:C500,"OPS")+COUNTIF('Registers & Trackers'!C5:C500,"OPS")+COUNTIF('Reports & Position Papers'!C5:C500,"OPS")+COUNTIF('Forms & Templates'!C5:C500,"OPS")+COUNTIF('HR Documents'!C5:C500,"OPS")+COUNTIF('General Documents'!C5:C500,"OPS")
B11: Forms & Templates | C11: =COUNTA('Forms & Templates'!A5:A500) | E11: OFF — Offshore | F11: =COUNTIF(Policies!C5:C500,"OFF")+COUNTIF('Procedures & SOPs'!C5:C500,"OFF")+COUNTIF('Risk Assessments'!C5:C500,"OFF")+COUNTIF('Registers & Trackers'!C5:C500,"OFF")+COUNTIF('Reports & Position Papers'!C5:C500,"OFF")+COUNTIF('Forms & Templates'!C5:C500,"OFF")+COUNTIF('HR Documents'!C5:C500,"OFF")+COUNTIF('General Documents'!C5:C500,"OFF")
B12: HR Documents | C12: =COUNTA('HR Documents'!A5:A500) | E12: SMS — Safety Mgmt | F12: =COUNTIF(Policies!C5:C500,"SMS")+COUNTIF('Procedures & SOPs'!C5:C500,"SMS")+COUNTIF('Risk Assessments'!C5:C500,"SMS")+COUNTIF('Registers & Trackers'!C5:C500,"SMS")+COUNTIF('Reports & Position Papers'!C5:C500,"SMS")+COUNTIF('Forms & Templates'!C5:C500,"SMS")+COUNTIF('HR Documents'!C5:C500,"SMS")+COUNTIF('General Documents'!C5:C500,"SMS")
B13: General Documents | C13: =COUNTA('General Documents'!A5:A500)
B15: STATUS BREAKDOWN
B16: Approved | C16: =COUNTIF(Policies!E5:E500,"Approved")+COUNTIF('Procedures & SOPs'!E5:E500,"Approved")+COUNTIF('Risk Assessments'!E5:E500,"Approved")+COUNTIF('Registers & Trackers'!E5:E500,"Approved")+COUNTIF('Reports & Position Papers'!E5:E500,"Approved")+COUNTIF('Forms & Templates'!E5:E500,"Approved")+COUNTIF('HR Documents'!E5:E500,"Approved")+COUNTIF('General Documents'!E5:E500,"Approved")
B17: Draft | C17: =COUNTIF(Policies!E5:E500,"Draft")+COUNTIF('Procedures & SOPs'!E5:E500,"Draft")+COUNTIF('Risk Assessments'!E5:E500,"Draft")+COUNTIF('Registers & Trackers'!E5:E500,"Draft")+COUNTIF('Reports & Position Papers'!E5:E500,"Draft")+COUNTIF('Forms & Templates'!E5:E500,"Draft")+COUNTIF('HR Documents'!E5:E500,"Draft")+COUNTIF('General Documents'!E5:E500,"Draft")
B18: Under Review | C18: =COUNTIF(Policies!E5:E500,"Under Review")+COUNTIF('Procedures & SOPs'!E5:E500,"Under Review")+COUNTIF('Risk Assessments'!E5:E500,"Under Review")+COUNTIF('Registers & Trackers'!E5:E500,"Under Review")+COUNTIF('Reports & Position Papers'!E5:E500,"Under Review")+COUNTIF('Forms & Templates'!E5:E500,"Under Review")+COUNTIF('HR Documents'!E5:E500,"Under Review")+COUNTIF('General Documents'!E5:E500,"Under Review")
B19: Superseded | C19: =COUNTIF(Policies!E5:E500,"Superseded")+COUNTIF('Procedures & SOPs'!E5:E500,"Superseded")+COUNTIF('Risk Assessments'!E5:E500,"Superseded")+COUNTIF('Registers & Trackers'!E5:E500,"Superseded")+COUNTIF('Reports & Position Papers'!E5:E500,"Superseded")+COUNTIF('Forms & Templates'!E5:E500,"Superseded")+COUNTIF('HR Documents'!E5:E500,"Superseded")+COUNTIF('General Documents'!E5:E500,"Superseded")
B20: Retired | C20: =COUNTIF(Policies!E5:E500,"Retired")+COUNTIF('Procedures & SOPs'!E5:E500,"Retired")+COUNTIF('Risk Assessments'!E5:E500,"Retired")+COUNTIF('Registers & Trackers'!E5:E500,"Retired")+COUNTIF('Reports & Position Papers'!E5:E500,"Retired")+COUNTIF('Forms & Templates'!E5:E500,"Retired")+COUNTIF('HR Documents'!E5:E500,"Retired")+COUNTIF('General Documents'!E5:E500,"Retired")
A21: SM/SEC/DOC/002 | B21: WAF OCIMF Due Diligence Questionnaire | C21: 1.0 | D21: April 2026 | E21: 03/04/2026 | F21: Darren Watts | G21: Active | H21: W-DOC-002 | I21: Due Diligence Assessment Questionnaire for West Africa operations — OCIMF PMSC Guidance 2022 aligned. 52 assessment questions across 8 compliance areas. Pre-engagement PMSC assessment tool.

Sheet Policies
C1: Seagull Maritime — Document Register — Policies
C2: SM/INT/REG/001 | POL
A4: Document Reference | B4: Document Title | C4: System | D4: Version | E4: Status | F4: Folder Location | G4: ISO Standard(s) | H4: Document Owner | I4: Issue Date | J4: Next Review | K4: Legacy Reference | L4: Notes
A5: SM/HSE/DOC/001 | B5: OH&S Management System Scope Statement | C5: HSE | D5: 1.0 | E5: Approved | F5: 01 - Policies/HSE Policies (45001) | G5: ISO 45001 (4.3) | H5: Group Compliance Director | I5: 03/02/2026 | J5: 03/02/2027 | L5: Defines scope and boundaries of OH&S management system
A6: SM/HSE/POL/001 | B6: Occupational Health & Safety Policy | C6: HSE | D6: 1.0 | E6: Approved | F6: 01 - Policies/HSE Policies (45001) | G6: ISO 45001 (5.2) | H6: Group Compliance Director | I6: 03/02/2026 | J6: 03/02/2027 | L6: CEO and GCD endorsement. Includes VPSHR and conflict zone commitments
A7: SM/HSE/POL/002 | B7: Environmental Policy | C7: HSE | D7: 1.0 | E7: Approved | F7: 01 - Policies/HSE Policies (45001) | G7: ISO 45001 | H7: Group Compliance Director
A8: SM/INT/POL/001 | B8: Anti-Bribery, Corruption and Business Ethics Policy | C8: INT | D8: 1.0 | E8: Approved | F8: 01 - Policies/Integrated Policies | G8: All | H8: Group Compliance Director
A9: SM/INT/POL/002 | B9: Code of Conduct | C9: INT | D9: 1.0 | E9: Approved | F9: 01 - Policies/Integrated Policies | G9: All | H9: Group Compliance Director
A10: SM/INT/POL/003 | B10: Equal Opportunities Policy | C10: INT | D10: 1.0 | E10: Approved | F10: 01 - Policies/Integrated Policies | G10: All | H10: Group Compliance Director
A11: SM/INT/POL/004 | B11: Grievance and Whistleblowing Policy | C11: INT | D11: 1.0 | E11: Approved | F11: 01 - Policies/Integrated Policies | G11: All | H11: Group Compliance Director
A12: SM/INT/POL/005 | B12: Personal Data Protection Policy | C12: INT | D12: 1.0 | E12: Approved | F12: 01 - Policies/Integrated Policies | G12: All | H12: Group Compliance Director
A13: SM/INT/POL/006 | B13: Recruitment Policy | C13: INT | D13: 1.0 | E13: Approved | F13: 01 - Policies/Integrated Policies | G13: All | H13: Group Compliance Director
A14: SM/INT/POL/007 | B14: Risk Management Policy | C14: INT | D14: 1.0 | E14: Approved | F14: 01 - Policies/Integrated Policies | G14: 45001 / 18788 / 28000 / 28007 | H14: Group Compliance Director
A15: SM/INT/POL/008 | B15: Social Media Policy | C15: INT | D15: 1.0 | E15: Approved | F15: 01 - Policies/Integrated Policies | G15: All | H15: Group Compliance Director
A16: SM/INT/POL/009 | B16: Training Policy | C16: INT | D16: 1.0 | E16: Approved | F16: 01 - Policies/Integrated Policies | G16: 45001 (7.2/7.3) / 18788 | H16: Group Compliance Director
A17: SM/QMS/POL/001 | B17: Quality Policy | C17: QMS | D17: 1.0 | E17: Approved | F17: 01 - Policies/Quality Policies (9001) | G17: ISO 9001 | H17: Group Compliance Director
A18: SM/QMS/POL/002 | B18: Quality Policy Statement | C18: QMS | D18: 1.0 | E18: Approved | F18: 01 - Policies/Quality Policies (9001) | G18: ISO 9001 | H18: Group Compliance Director
... A22: SM/SEC/POL/004 | B22: Security Policy Statement | C22: SEC | D22: 1.0 | E22: Approved | F22: 01 - Policies/Security Policies (18788 - 28007 - 28000) | G22: 18788 / 28007 / 28000 | H22: Group Compliance Director
A23: SM/INT/POL/010 | B23: Drugs and Alcohol Policy | C23: INT | D23: 1.0 | E23: Approved | F23: 01 - Policies/Integrated Policies/Controlled Drafts | G23: 45001 / 18788 | H23: Group Compliance Director | I23: 08/04/2026

Sheet Procedures & SOPs
C1: Seagull Maritime — Document Register — Procedures & SOPs
C2: SM/INT/REG/001 | PRO | SOP | ANN
A4: Document Reference | B4: Document Title | C4: System | D4: Version | E4: Status | F4: Folder Location | G4: ISO Standard(s) | H4: Document Owner | I4: Issue Date | J4: Next Review | K4: Legacy Reference | L4: Notes
A5: SM/OPS/SOP/001 | B5: Indian Ocean Piracy Operations SOP | C5: OPS | E5: Approved | F5: 02 / Operational SOPs / IOR | G5: 28007 / 18788 | H5: Group Compliance Director | K5: SMS/SOP/IO/001 | L5: Migrate ref on next amendment (Shell findings)
A6: SM/OPS/SOP/002 | B6: WAF SEV Operations SOP | C6: OPS | D6: 1.0 | E6: Approved | F6: 02 / Operational SOPs / WAF | G6: 28007 / 18788 | H6: Group Compliance Director | I6: 03/04/2026 | J6: Annual | L6: S26 rebuild. Tracked changes: VPSHR, BMP-MS, Safety App, training refs. PG SOP entry removed — never actioned.
A7: SM/OFF/PRO/001 | B7: SEV Critical Spares Risk Assessment Procedure | C7: OFF | D7: 1.0 | E7: Approved | F7: 10 / Seagull Offshore / Procedures | G7: 9001 | H7: Group Compliance Director | I7: 2026 | J7: 2027 | K7: SM PRO-SEV-RA-001
A8: SM/INT/PRO/002 | B8: Control of Documents | C8: INT | D8: 1.0 | E8: Approved | F8: 02 - Procedures and SOPs | G8: 9001 / 18788 / 28007 / 28000 / 45001 | H8: Group Compliance Director | I8: 30/03/2026 | J8: 30/03/2027 | K8: MSP-A-01 / OHSP14 / SOP-1001 | L8: Migrated from SM/PRO/DOC/001 (Option A, 30 Mar 2026). Supersedes all prior doc control procedures
A9: SM/INT/PRO/003 | B9: Internal Audit | C9: INT | D9: 1.0 | E9: Approved | F9: 02 - Procedures and SOPs | G9: 9001 / 18788 / 28007 / 28000 / 45001 / 19011 | H9: Group Compliance Director | I9: 30/03/2026 | J9: 30/03/2027 | L9: Migrated from SM/PRO/IA/001 (Option A, 30 Mar 2026). Supersedes all prior IA procedures
A10: SM/INT/PRO/001 | B10: Non-Conformance, OFI and Corrective Action Management | C10: INT | D10: 1.0 | E10: Approved | F10: 02 - Procedures and SOPs | G10: 9001 / 18788 / 28007 / 28000 / 45001 | H10: Group Compliance Director | I10: 30/03/2026 | J10: 30/03/2027 | L10: Approved by Pavel Shparber (CEO) and Darren Watts (GCD)
A11: SM/HSE/PRO/001 | B11: Hazard Identification and Risk Assessment Procedure | C11: HSE | D11: 1.0 | E11: Approved | F11: 02 - Procedures and SOPs / HSE Procedures | G11: 45001 | H11: Group Compliance Director | I11: 31/03/2026 | J11: 31/03/2027
A12: SM/SEC/PRO/001 | B12: Security and Business Risk Assessment Procedure | C12: SEC | D12: 1.0 | E12: Approved | F12: 02 - Procedures and SOPs / Security Procedures | G12: 28007 / 18788 / 28000 | H12: Group Compliance Director
A13: SM/HSE/PRO/002 | B13: Legal and Regulatory Compliance Procedure | C13: HSE | D13: 1.0 | E13: Approved | F13: 02 - Procedures and SOPs / HSE Procedures | G13: 45001 (6.1.3 / 9.1.2) | H13: Group Compliance Director | I13: 01/04/2026
A14: SM/INT/PRO/004 | B14: External References and Standards Procedure | C14: INT | D14: 1.0 | E14: Approved | F14: 02 - Procedures and SOPs | G14: 9001 / 18788 / 28007 / 28000 / 45001 | H14: Group Compliance Director | I14: 01/04/2026
A15: SM/SEC/PRO/002 | B15: Due Diligence Response Procedure | C15: SEC | D15: 1.1 | E15: Approved | F15: 02 / Security Procedures | G15: ISO 28007 (4.4.6) / ISO 18788 (A.4.3.2, A.9.3) | H15: Group Compliance Director | I15: 04/04/2026 | J15: 02/04/2027 | L15: S28 update: WAF portal and DOC-002 references added, PG removed. 11 tracked changes.
A16: SM/INT/PRO/005 | B16: Control of Records | C16: INT | D16: 1.0 | E16: Approved | F16: 02 - Procedures and SOPs | G16: ISO 45001 (7.5) | H16: Group Compliance Director
A17: SM/INT/PRO/006 | B17: Incident and Crisis Management | C17: INT | D17: 1.0 | E17: Approved | F17: 02 - Procedures and SOPs | G17: 45001 / 18788 | H17: Group Compliance Director
A18: SM/INT/PRO/007 | B18: PCASP Induction and Deployment | C18: INT | D18: 1.0 | E18: Approved | F18: 02 - Procedures and SOPs | G18: 28007 / 18788 | H18: Group Compliance Director
A19: SM/INT/PRO/008 | B19: PCASP Recruitment and Screening | C19: INT | D19: 1.0 | E19: Approved | F19: 02 - Procedures and SOPs | G19: 28007 / 18788 | H19: Group Compliance Director
A20: SM/INT/PRO/008-A | B20: PCASP Recruitment and Screening (Shell Supplement) | C20: INT | D20: 1.0 | E20: Approved | F20: 02 - Procedures and SOPs | G20: 28007 / Shell | H20: Group Compliance Director
A21: SM/INT/PRO/009 | B21: Firearms Competency | C21: INT | D21: 1.0 | E21: Approved | F21: 02 - Procedures and SOPs | G21: 28007 / 18788 | H21: Group Compliance Director
A22: SM/SEC/PRO/003 | B22: Rules on the Use of Force | C22: SEC | D22: 1.0 | E22: Approved | F22: 02 / Security Procedures | G22: 28007 / 18788 | H22: Group Compliance Director
A23: SM/SEC/PRO/004 | B23: Security Escort Vessel Approval Procedure | C23: SEC | D23: 1.0 | E23: Approved | F23: 02 / Security Procedures | G23: 28007 / 18788 / 9001 | H23: Group Compliance Director | I23: 03/04/2026 | J23: Annual | K23: SM/PRO/SEV/001 | L23: S26 rebuild from legacy. S28 major update: documentation requirements tables (V01-V27 + Shell), operational exceptions, transitional compliance, document storage with folder mockups.
A24: SM/SEC/PRO/005 | B24: Supplier Approval — Security Escort Vessel Providers | C24: SEC | D24: 1.0 | E24: Approved | F24: 02 / Security Procedures | G24: 18788 / 9001 / 28007 / 45001 | H24: Group Compliance Director | I24: 03/04/2026 | J24: Annual | K24: SM/PRO/SASEV/001 | L24: S26 rebuild from legacy. S28 update: Provider docs table (P01-P11), DD questionnaire mapping to standards, exclusions, basis of approval, priority of use, review cycle, document storage.
A25: SM/OPS/SOP/001-A | B25: IOR SOP — Annex A — Deployment and Embarkation | C25: OPS | D25: 1.0 | E25: Approved | F25: 02 / Operational SOPs / IOR / SOP | G25: 28007 / 18788 | H25: Group Compliance Director
A26: SM/OPS/SOP/001-B | B26: IOR SOP — Annex B — Vessel Familiarisation | C26: OPS | D26: 1.0 | E26: Approved | F26: 02 / Operational SOPs / IOR / SOP | G26: 28007 / 18788 | H26: Group Compliance Director
A27: SM/OPS/SOP/001-C | B27: IOR SOP — Annex C — Vessel Hardening & Mitigation Measures | C27: OPS | D27: 1.0 | E27: Approved | F27: 02 / Operational SOPs / IOR / SOP | G27: 28007 / 18788 | H27: Group Compliance Director
A28: SM/OPS/SOP/001-D | B28: IOR SOP — Annex D — Onboard Routines | C28: OPS | D28: 1.0 | E28: Approved | F28: 02 / Operational SOPs / IOR / SOP | G28: 28007 / 18788 | H28: Group Compliance Director
A29: SM/OPS/SOP/001-E | B29: IOR SOP — Annex E — Vessel Defence | C29: OPS | D29: 1.0 | E29: Approved | F29: 02 / Operational SOPs / IOR / SOP | G29: 28007 / 18788 | H29: Group Compliance Director
A30: SM/OPS/SOP/001-F | B30: IOR SOP — Annex F — Incident Management | C30: OPS | D30: 1.0 | E30: Approved | F30: 02 / Operational SOPs / IOR / SOP | G30: 28007 / 18788 | H30: Group Compliance Director
A31: SM/OPS/SOP/001-G | B31: IOR SOP — Annex G — Weapons & Equipment Management | C31: OPS | D31: 1.0 | E31: Approved | F31: 02 / Operational SOPs / IOR / SOP | G31: 28007 / 18788 | H31: Group Compliance Director
A32: SM/OPS/SOP/001-H | B32: IOR SOP — Annex H — Disembarkation and Post Transit | C32: OPS | D32: 1.0 | E32: Approved | F32: 02 / Operational SOPs / IOR / SOP | G32: 28007 / 18788 | H32: Group Compliance Director
A33: SM/INT/PRO/010 | B33: Training and Competence Management Procedure | C33: INT | D33: 1.0 | E33: Approved | F33: 02 / Procedures and SOPs | G33: 45001 Cl. 7.2 / 7.3 | H33: Group Compliance Director
A34: SM/OPS/SOP/002-A | B34: WAF SOP — Annex A — MSLO Operations | C34: OPS | D34: 1.0 | E34: Approved | F34: 02 / Operational SOPs / WAF | G34: 28007 / 18788 | H34: Group Compliance Director | I34: 03/04/2026 | L34: S26 creation. Tracked changes: VPSHR, Safety App, training refs.
A35: SM/INT/PRO/011 | B35: Staff Recruitment Procedure | C35: INT | D35: 1.0 | E35: Approved | F35: 02 - Procedures and SOPs | G35: 9001 7.1.2 / 18788 7.1 / 45001 7.2 | H35: Group Compliance Director | I35: 06/04/2026 | J35: 06/04/2027 | K35: SM PRO - Recruitment Employed Staff | L35: Replaces legacy recruitment procedure
A36: SM/INT/PRO/012 | B36: Staff Training and Competence Procedure | C36: INT | D36: 1.0 | E36: Approved | F36: 02 - Procedures and SOPs | G36: 9001 7.2 / 45001 7.2-7.3 / 18788 7.2 / 28007 7.2 | H36: Group Compliance Director | I36: 06/04/2026 | J36: 06/04/2027 | K36: N/A | L36: New procedure — staff training (complements PRO/010 for PCASP)
A37: SM/INT/PRO/013 | B37: Management of Change Procedure | C37: INT | D37: 1.0 | E37: Approved | F37: 02 - Procedures and SOPs | G37: 9001 6.3 / 45001 8.1.3 / 18788 8.1 / 28007 8.1 | H37: Group Compliance Director | I37: 07/04/2026 | J37: 07/04/2027 | K37: SM/PRO/CHA/001 | L37: Supersedes SM/PRO/CHA/001. Shell OFI-001 / CWP 1.06.
A38: SM/HSE/PRO/003 | B38: Emergency Preparedness and Response Procedure | C38: HSE | D38: 1.0 | E38: Approved | F38: 02 / HSE Procedures | G38: 45001 (8.2) / 18788 (8.3) / 28007 / 28000 | H38: Group Compliance Director | I38: 08/04/2026 | J38: 08/04/2027 | K38: SOP-2002, SOP-2005
A39: SM/INT/PRO/014 | B39: Worker Consultation and Participation Procedure | C39: INT | D39: 1.0 | E39: Approved | F39: 02 / Integrated | G39: 45001 (5.4) / 18788 (5.3.3) | H39: Group Compliance Director | I39: 08/04/2026 | J39: 08/04/2027
A40: SM/INT/PRO/015 | B40: Continual Improvement Procedure | C40: INT | D40: 1.0 | E40: Approved | F40: 02 / Integrated | G40: 45001 (10.3) / 18788 (10.2) / 9001 (10.3) | H40: Group Compliance Director | I40: 08/04/2026 | J40: 08/04/2027
A41: SM/INT/PRO/016 | B41: Internal and External Communications Procedure | C41: INT | D41: 1.0 | E41: Active | F41: 02 - Procedures and SOPs/Integrated Procedures/Controlled Drafts | G41: 45001 (7.4) / 9001 (7.4) / 18788 (7.4) | H41: Group Compliance Director | I41: 08/04/2026 | J41: 08/04/2027 | L41: S34. Emergency prep, IRT tabletop framework.
...

Sheet Risk Assessments
C1: Seagull Maritime — Document Register — Risk Assessments
C2: SM/INT/REG/001 | RA
A4: Document Reference | B4: Document Title | C4: System | D4: Version | E4: Status | F4: Folder Location | G4: ISO Standard(s) | H4: Document Owner | I4: Issue Date | J4: Next Review | K4: Legacy Reference | L4: Notes
A5: SM/HSE/RA/001 | B5: Vessel Evacuation and Guarding Operations H&S RA | C5: HSE | D5: 1.0 | E5: Approved | F5: 03 / RA-003 Series | G5: 45001 | H5: Group Compliance Director | I5: 2026 | J5: 2027 | K5: SM RA-003 | L5: RA-003 pattern (5x5 H&S)
A6: SM/SEC/RA/001 | B6: IOR Piracy Operations Security & Business RA | C6: SEC | D6: 1.0 | E6: Approved | F6: 03 / RA-004 Series | G6: 18788 / 28000 | H6: Group Compliance Director | I6: 2026 | J6: 2027 | K6: SM RA-004 IOR | L6: RA-004 pattern (PESTLE)
A7: SM/SEC/RA/002 | B7: WAF GOG Operations Security & Business RA | C7: SEC | D7: 1.0 | E7: Approved | F7: 03 / RA-004 Series | G7: 18788 / 28000 | H7: Group Compliance Director | I7: 2026 | J7: 2027 | K7: SM RA-004 WAF | L7: RA-004 pattern (PESTLE)
A8: SM/SEC/RA/003 | B8: PG Vessel Evacuation and Guarding Security & Business RA | C8: SEC | D8: 1.0 | E8: Archived | F8: 03 / RA-004 Series | G8: 18788 / 28000 | H8: Group Compliance Director | I8: 2026 | J8: 2027 | K8: SM RA-004 PG | L8: PG operations never actioned. Files moved to Misc (S17). Archived S28.
A9: SM/OFF/RA/001 | B9: Critical Spares RA - MV Mediator IV | C9: OFF | D9: 1.0 | E9: Approved | F9: 10 / Seagull Offshore / Risk Assessments | G9: 9001 | H9: Group Compliance Director | I9: 2026 | J9: 2027 | K9: SM RA-SEV MED4 001
A10: SM/HSE/RA/002 | B10: Vessel Transfer Operations H&S Risk Assessment | C10: HSE | D10: 1.0 | E10: Approved | F10: 03 - Risk Assessments/RA-003 Series (HS - ISO 45001) | G10: ISO 45001 (6.1.2) | H10: Group Compliance Director | I10: 31/03/2026 | J10: 30/09/2026 | L10: RA-003 pattern. 24 hazards. Dashboard + methodology. Gold standard template.
A11: SM/HSE/RA/003 | B11: Security Duties Client Vessel H&S Risk Assessment | C11: HSE | D11: 1.0 | E11: Approved | F11: 03 - Risk Assessments/RA-003 Series (HS - ISO 45001) | G11: ISO 45001 (6.1.2) | H11: Group Compliance Director | I11: 31/03/2026 | J11: 30/09/2026 | L11: RA-003 pattern. 20 hazards. Merged from existing RA + PSS Security Watch.
A12: SM/HSE/RA/004 | B12: Weapons Handling and Armoury Operations H&S Risk Assessment | C12: HSE | D12: 1.0 | E12: Approved | F12: 03 - Risk Assessments/RA-003 Series (HS - ISO 45001) | G12: ISO 45001 (6.1.2) | H12: Group Compliance Director | I12: 31/03/2026 | J12: 30/09/2026 | L12: RA-003 pattern. 16 hazards. Source: PSS Armoury Operations RA.
A13: SM/HSE/RA/005 | B13: RHIB and Craft Launch Operations H&S Risk Assessment | C13: HSE | D13: 1.0 | E13: Approved | F13: 03 - Risk Assessments/RA-003 Series (HS - ISO 45001) | G13: ISO 45001 (6.1.2) | H13: Group Compliance Director | I13: 31/03/2026 | J13: 30/09/2026 | L13: RA-003 pattern. 14 hazards. Source: PSS Craft Launch RA.
A14: SM/HSE/RA/006 | B14: Vessel Routine Operations H&S Risk Assessment | C14: HSE | D14: 1.0 | E14: Approved | F14: 03 - Risk Assessments/RA-003 Series (HS - ISO 45001) | G14: ISO 45001 (6.1.2) | H14: Group Compliance Director | I14: 31/03/2026 | J14: 30/09/2026 | L14: RA-003 pattern. 18 hazards. Source: PSS Routine Ops + Galley RAs merged.
A15: SM/HSE/RA/007 | B15: Office Workplace H&S Risk Assessment | C15: HSE | D15: 1.0 | E15: Approved | F15: 03 - Risk Assessments/RA-003 Series (HS - ISO 45001) | G15: ISO 45001 (6.1.2) | H15: Group Compliance Director | I15: 31/03/2026 | J15: 30/09/2026 | L15: RA-003 pattern. 14 hazards. Dubai, Piraeus, Lagos offices.
A16: SM/HSE/RA/008 | B16: Remote Working H&S Risk Assessment | C16: HSE | D16: 1.0 | E16: Approved | F16: 03 - Risk Assessments/RA-003 Series (HS - ISO 45001) | G16: ISO 45001 (6.1.2) | H16: Group Compliance Director | I16: 31/03/2026 | J16: 30/09/2026 | L16: RA-003 pattern. 12 hazards. DSE, ergonomics, lone working, mental health.
A17: SM/HSE/RA/009 | B17: Heat Stress H&S Risk Assessment | C17: HSE | D17: 1.0 | E17: Approved | F17: 03 - Risk Assessments/RA-003 Series (HS - ISO 45001) | G17: ISO 45001 (6.1.2) | H17: Group Compliance Director | I17: 31/03/2026 | J17: 30/09/2026 | L17: RA-003 pattern. 12 hazards. All hot-climate ops and offices.
A18: SM/HSE/RA/010 | B18: Night Operations H&S Risk Assessment | C18: HSE | D18: 1.0 | E18: Approved | F18: 03 - Risk Assessments/RA-003 Series (HS - ISO 45001) | G18: ISO 45001 (6.1.2) | H18: Group Compliance Director | I18: 01/04/2026 | J18: 01/10/2026 | L18: RA-003 pattern. 14 hazards. Night-specific hazard layer overlaying all activity RAs.

Sheet Registers & Trackers
C1: Seagull Maritime — Document Register — Registers & Trackers
C2: SM/INT/REG/001 | REG
A4: Document Reference | B4: Document Title | C4: System | D4: Version | E4: Status | F4: Folder Location | G4: ISO Standard(s) | H4: Document Owner | I4: Issue Date | J4: Next Review | K4: Legacy Reference | L4: Notes
A5: SM/INT/REG/001 | B5: Document Register | C5: INT | D5: 2.0 | E5: Approved | F5: 04 - Registers and Trackers | G5: All | H5: Group Compliance Director | I5: 23/03/2026 | J5: 23/03/2027 | L5: This register
A6: SM/INT/CMP/002 | B6: Combined Work Programme | C6: INT | D6: 2.0 | E6: Approved | F6: 04 - Registers and Trackers | G6: All | H6: Group Compliance Director | I6: 23/03/2026 | J6: Ongoing | L6: Master programme - 45001 + Shell
A7: SM/INT/REG/003 | B7: Internal Audit Schedule 2026 | C7: INT | D7: 1.0 | E7: Approved | F7: 07 / Internal Audits | G7: 9001 / 19011 | H7: Group Compliance Director | I7: 25/03/2026 | J7: 01/01/2027 | L7: 1-year rolling schedule
A8: SM/INT/REG/004 | B8: NCR, OFI and CAPA Register | C8: INT | D8: 1.0 | E8: Approved | F8: 04 - Registers and Trackers | G8: 9001 / 18788 / 28007 / 28000 / 45001 | H8: Group Compliance Director | I8: 30/03/2026 | J8: 30/03/2027 | L8: Approved by Pavel Shparber (CEO) and Darren Watts (GCD)
A9: SM/INT/REG/005 | B9: Reconciliation Matrix | C9: INT | D9: 1.0 | E9: Approved | F9: 04 - Registers and Trackers | G9: All | H9: Group Compliance Director | I9: 30/03/2026 | J9: 30/03/2027 | L9: Cross-reference of all tracked items across registers and programmes
A10: SM/HSE/REG/001 | B10: Interested Parties Register | C10: HSE | D10: 1.0 | E10: Approved | F10: 01 - Policies/HSE Policies (45001) | G10: ISO 45001 (4.2) | ISO 18788 (4.2) | ISO 28000 (4.2) | ISO 9001 (4.2) | H10: Group Compliance Director | I10: 03/02/2026 | J10: 03/02/2027 | L10: 21 interested parties. Power/Interest Matrix. Iran conflict flagged in review notes
A11: SM/INT/REG/006 | B11: Company Objectives Register | C11: INT | D11: 1.0 | E11: Approved | F11: 04 - Registers and Trackers | G11: 9001 / 18788 / 28007 / 28000 / 45001 | H11: Group Compliance Director | I11: 31/03/2026 | J11: 30/09/2026
A12: SM/SEC/REG/001 | B12: Flag State Requirements Register | C12: SEC | D12: 1.0 | E12: Approved | F12: 04 - Registers and Trackers | G12: 28007 / 18788 / 28000 | H12: Group Compliance Director | I12: 01/04/2026
A13: SM/HSE/REG/002 | B13: Legal and Regulatory Requirements Register | C13: HSE | D13: 1.0 | E13: Approved | F13: 04 - Registers and Trackers | G13: 45001 (6.1.3) / 18788 / 28007 / 28000 / 9001 | H13: Group Compliance Director | I13: 01/04/2026
A14: SM/INT/REG/007 | B14: External Standards and References Register | C14: INT | D14: 1.0 | E14: Approved | F14: 04 - Registers and Trackers | G14: 9001 / 18788 / 28007 / 28000 / 45001 | H14: Group Compliance Director | I14: 01/04/2026
A15: SM/INT/REG/008 | B15: Training and Competence Matrix | C15: INT | D15: 1.0 | E15: Approved | F15: 04 - Registers and Trackers | G15: 45001 (7.2/7.3) / 9001 / 18788 / 28007 | H15: Group Compliance Director | I15: 03/04/2026 | J15: 03/10/2026 | L15: 20 courses × 3 role categories × 41 personnel. Derived from SM/INT/PRO/010.
A16: SM/INT/REG/009 | B16: Change Request Register | C16: INT | D16: 1.0 | E16: Approved | F16: 04 - Registers and Trackers | G16: 9001 6.3 / 45001 8.1.3 / 18788 8.1 | H16: Group Compliance Director | I16: 07/04/2026 | J16: 07/04/2027 | L16: Tracks all change requests per SM/INT/PRO/013.
A17: SM/INT/REG/010 | B17: Supplier and Subcontractor Register | C17: INT | D17: 1.0 | E17: Active | F17: 04 - Registers and Trackers | G17: 45001 Cl. 8.1.4 / 9001 8.4 | H17: Group Compliance Director | I17: 08/04/2026 | J17: 08/04/2027 | L17: S34. Unified register: General, SEV Suppliers, Approved SEVs, Subcontractors.

Sheet Reports & Position Papers
C1: Seagull Maritime — Document Register — Reports & Position Papers
C2: SM/INT/REG/001 | RPT | CPP | SOW
A4: Document Reference | B4: Document Title | C4: System | D4: Version | E4: Status | F4: Folder Location | G4: ISO Standard(s) | H4: Document Owner | I4: Issue Date | J4: Next Review | K4: Legacy Reference | L4: Notes
A5: SM/INT/CPP/001 | B5: Compliance Position Paper - MV Vladimir Boarding | C5: INT | D5: 1.0 | E5: Approved | F5: 08 / Compliance Position Papers | G5: 18788 / 28007 | H5: Group Compliance Director | I5: 23/03/2026 | J5: N/A | L5: Confidential - Directors only
A6: SM/INT/SOW/001 | B6: Scope of Work - MV Vladimir Monitoring | C6: INT | D6: 0.1 | E6: Draft | F6: 08 / Compliance Position Papers | G6: 18788 / 28007 | H6: Group Compliance Director | I6: 23/03/2026 | J6: N/A | L6: DRAFT - Theoretical only
A7: SM/INT/RPT/001 | B7: Internal Audit Programme Review and Gap Analysis | C7: INT | D7: 1.0 | E7: Approved | F7: 07 / Internal Audits | G7: All | H7: Group Compliance Director | I7: 25/03/2026 | J7: N/A | L7: Initial gap analysis driving audit programme
A8: SM/SEC/RPT/001 | B8: Internal Audit Report - Document Control | C8: SEC | D8: 1.0 | E8: Approved | F8: 07 / Internal Audits | G8: 9001 / 18788 | H8: Group Compliance Director | I8: 28/03/2026 | J8: N/A | L8: SM-IA-26-001
A9: SM/SEC/RPT/002 | B9: Internal Audit Report - Risk Management | C9: SEC | D9: 1.0 | E9: Approved | F9: 07 / Internal Audits | G9: 18788 / 28007 / 45001 | H9: Group Compliance Director | I9: 29/03/2026 | J9: N/A | L9: SM-IA-26-002
A10: SM/HSE/RPT/001 | B10: IRT Exercise Report - Office Fire | C10: HSE | D10: 1.0 | E10: Approved | F10: 08 - Reports and Records | G10: 45001 (8.2) | H10: Group Compliance Director | I10: 27/03/2026

Sheet Forms & Templates
C1: Seagull Maritime — Document Register — Forms & Templates
C2: SM/INT/REG/001 | FORM | TPL
A4: Document Reference | B4: Document Title | C4: System | D4: Version | E4: Status | F4: Folder Location | G4: ISO Standard(s) | H4: Document Owner | I4: Issue Date | J4: Next Review | K4: Legacy Reference | L4: Notes
A5: SM/INT/TPL/001 | B5: Register Template | C5: INT | D5: 1.0 | E5: Approved | F5: 09 / Register Templates | G5: All | H5: Group Compliance Director | I5: 23/03/2026 | J5: 23/03/2027 | L5: Master template for all xlsx registers
A6: SM/INT/TPL/002 | B6: Procedure Template | C6: INT | D6: 1.0 | E6: Approved | F6: 09 / Templates / Word | G6: All | H6: Group Compliance Director | I6: 30/03/2026 | J6: 30/03/2027 | L6: Standard template for all procedures
A7: SM/INT/FORM/001 | B7: Non-Conformance Report Form | C7: INT | D7: 1.0 | E7: Approved | F7: 09 - Templates and Forms | G7: 9001 / 18788 / 28007 / 28000 / 45001 | H7: Group Compliance Director | I7: Pavel Shparber, CEO / Darren Watts, GCD | J7: 30 March 2026
A8: SM/OPS/FORM/001 | B8: RUF Card | C8: OPS | D8: 1.0 | E8: Approved | F8: 02 / Operational SOPs / RUF Forms | G8: 28007 / 18788 | H8: Group Compliance Director
A9: SM/OPS/FORM/002 | B9: Statement of Understanding (MSO) | C9: OPS | D9: 1.0 | E9: Approved | F9: 02 / Operational SOPs / RUF Forms | G9: 28007 / 18788 | H9: Group Compliance Director
A10: SM/OPS/FORM/003 | B10: Statement of Understanding (Master/OOW) | C10: OPS | D10: 1.0 | E10: Approved | F10: 02 / Operational SOPs / RUF Forms | G10: 28007 / 18788 | H10: Group Compliance Director
A11: SM/OPS/FORM/004 | B11: Release Authorisation | C11: OPS | D11: 1.0 | E11: Approved | F11: 02 / Operational SOPs / RUF Forms | G11: 28007 / 18788 | H11: Group Compliance Director
A12: SM/OPS/FORM/005 | B12: Incident Report | C12: OPS | D12: 1.0 | E12: Approved | F12: 02 / Operational SOPs / RUF Forms | G12: 28007 / 18788 | H12: Group Compliance Director
A13: SM/SEC/FORM/001 | B13: Security Escort Vessel (SEV) Checklist | C13: SEC | D13: 1.0 | E13: Approved | F13: 09 - Templates and Forms | G13: 28007 / 18788 / 9001 | H13: Group Compliance Director | I13: 03/04/2026 | J13: Annual | L13: S26 initial build. S28 rebuilt: 27 mandatory items (V01-V27), Provider Documentation sheet (P01-P11), logos, source attribution, dashboard.
A14: SM/SEC/FORM/002 | B14: WAF Escorting Due Diligence Checklist | C14: SEC | D14: 1.0 | E14: Approved | F14: 09 - Templates and Forms | G14: 18788 / 28007 / 9001 | H14: Group Compliance Director | I14: 03/04/2026 | J14: Annual | L14: S26 initial build. S28 rebuilt: Source column added to all 8 sections (OCIMF/Shell/ISO/VPSHR attribution), logos, Remarks column, updated dashboard + instructions.
A15: SM/INT/FORM/002 | B15: New Starter Checklist | C15: INT | D15: 1.0 | E15: Approved | F15: 09 - Templates and Forms | G15: 9001 7.2 / 45001 7.2 | H15: Group Compliance Director | I15: 06/04/2026 | J15: 06/04/2027 | L15: Form for dept managers to track new starter onboarding
A16: SM/INT/FORM/003 | B16: Change Request Form | C16: INT | D16: 1.0 | E16: Approved | F16: 09 - Templates and Forms | G16: 9001 6.3 / 45001 8.1.3 / 18788 8.1 | H16: Group Compliance Director | I16: 07/04/2026 | J16: 07/04/2027 | L16: Form for raising change requests per SM/INT/PRO/013.
A17: SM/INT/FORM/004 | B17: Supplier Approval Form | C17: INT | D17: 1.0 | E17: Active | F17: 09 - Templates and Forms | G17: 45001 Cl. 8.1.4 / 9001 8.4 | H17: Group Compliance Director | I17: 08/04/2026 | J17: 08/04/2027 | L17: S34. Word form sent to suppliers. Clone from FORM-003.
A18: SM/INT/FORM/005 | B18: Supplier Corrective Action Report | C18: INT | D18: 1.0 | E18: Active | F18: 09 - Templates and Forms | G18: 45001 Cl. 8.1.4 / 9001 8.4 | H18: Group Compliance Director | I18: 08/04/2026 | J18: 08/04/2027 | L18: S34. SCAR form. Clone from FORM-003.
A19: SM/INT/FORM/006 | B19: Supplier Approval Checklist | C19: INT | D19: 1.0 | E19: Active | F19: 09 - Templates and Forms | G19: 45001 Cl. 8.1.4 / 9001 8.4 | H19: Group Compliance Director | I19: 08/04/2026 | J19: 08/04/2027 | L19: S34. Excel internal mirror of FORM/004.
A20: SM/SEC/FORM/003 | B20: SEV Vessel Information Form | C20: SEC | D20: 1.0 | E20: Active | F20: 09 - Templates and Forms | G20: ISO 28007 / 18788 | H20: Group Compliance Director | I20: 08/04/2026 | J20: 08/04/2027 | L20: S34. Word form sent to SEV providers. One per vessel.
A21: SM/SEC/FORM/004 | B21: SEV Provider Due Diligence Form | C21: SEC | D21: 1.0 | E21: Active | F21: 09 - Templates and Forms | G21: ISO 28007 / 18788 | H21: Group Compliance Director | I21: 08/04/2026 | J21: 08/04/2027 | L21: S34. Word form, 49 DD questions (corrected from PMSC framing).
A22: SM/OPS/FORM/006 | B22: Daily Report | C22: OPS | D22: 1.0 | E22: Approved | F22: 09 - Templates and Forms/TL Forms | G22: 28007 / 18788 | H22: Group Compliance Director | I22: 08/04/2026
A23: SM/OPS/FORM/007 | B23: Embarkation Report | C23: OPS | D23: 1.0 | E23: Approved | F23: 09 - Templates and Forms/TL Forms | G23: 28007 / 18788 | H23: Group Compliance Director | I23: 08/04/2026
A24: SM/OPS/FORM/008 | B24: Second Day Report | C24: OPS | D24: 1.0 | E24: Approved | F24: 09 - Templates and Forms/TL Forms | G24: 28007 / 18788 | H24: Group Compliance Director | I24: 08/04/2026
A25: SM/OPS/FORM/009 | B25: Crossing 60°E Report | C25: OPS | D25: 1.0 | E25: Approved | F25: 09 - Templates and Forms/TL Forms | G25: 28007 / 18788 | H25: Group Compliance Director | I25: 08/04/2026
A26: SM/OPS/FORM/010 | B26: Port Report | C26: OPS | D26: 1.0 | E26: Approved | F26: 09 - Templates and Forms/TL Forms | G26: 28007 / 18788 | H26: Group Compliance Director | I26: 08/04/2026
A27: SM/OPS/FORM/011 | B27: Exit Port Report | C27: OPS | D27: 1.0 | E27: Approved | F27: 09 - Templates and Forms/TL Forms | G27: 28007 / 18788 | H27: Group Compliance Director | I27: 08/04/2026
A28: SM/OPS/FORM/012 | B28: 48 Hours to Disembarkation Report | C28: OPS | D28: 1.0 | E28: Approved | F28: 09 - Templates and Forms/TL Forms | G28: 28007 / 18788 | H28: Group Compliance Director | I28: 08/04/2026
A29: SM/OPS/FORM/013 | B29: Disembarkation Report | C29: OPS | D29: 1.0 | E29: Approved | F29: 09 - Templates and Forms/TL Forms | G29: 28007 / 18788 | H29: Group Compliance Director | I29: 08/04/2026
A30: SM/OPS/FORM/014 | B30: Incident Report | C30: OPS | D30: 1.0 | E30: Approved | F30: 09 - Templates and Forms/TL Forms | G30: 28007 / 18788 / 45001 | H30: Group Compliance Director | I30: 08/04/2026
A31: SM/OPS/FORM/015 | B31: Embarked Training Return | C31: OPS | D31: 1.0 | E31: Approved | F31: 09 - Templates and Forms/TL Forms | G31: 28007 / 45001 (7.2) | H31: Group Compliance Director | I31: 08/04/2026
A32: SM/OPS/FORM/016 | B32: First Aid Kit Check | C32: OPS | D32: 1.0 | E32: Approved | F32: 09 - Templates and Forms/TL Forms | G32: 45001 | H32: Group Compliance Director | I32: 08/04/2026
A33: SM/OPS/FORM/017 | B33: Vessel Details Form | C33: OPS | D33: 1.0 | E33: Approved | F33: 09 - Templates and Forms/TL Forms | G33: 28007 / 18788 | H33: Group Compliance Director | I33: 08/04/2026

Sheet HR Documents
C1: Seagull Maritime — Document Register — HR Documents
C2: SM/INT/REG/001 | JD
A4: Document Reference | B4: Document Title | C4: System | D4: Version | E4: Status | F4: Folder Location | G4: ISO Standard(s) | H4: Document Owner | I4: Issue Date | J4: Next Review | K4: Legacy Reference | L4: Notes
A5: SM/INT/JD/001 | B5: QHSE Manager Job Description | C5: INT | D5: 1.0 | E5: Approved | F5: 05 / Job Descriptions | G5: All | H5: Group Compliance Director | I5: 06/03/2026 | J5: 06/03/2027 | K5: SM-JD-QHSE Manager-06.03.2026
A6: SM/INT/JD/002 | B6: Compliance Administrator Job Description | C6: INT | D6: 1.0 | E6: Approved | F6: 05 - Human Resources / Job Descriptions | G6: All | H6: Group Compliance Director | I6: Pavel Shparber, CEO / Darren Watts, GCD | J6: 30 March 2026
A7: SM/INT/JD/003 | B7: QHSE Manager | C7: INT | D7: 1.0 | E7: Approved | F7: 05 / Job Descriptions | G7: All | H7: Group Compliance Director | I7: 30 March 2026 | J7: As per Document Register defined review date, or upon significant change to role
A8: SM/INT/JD/004 | B8: Group Compliance Director | C8: INT | D8: 1.0 | E8: Approved | F8: 05 / Job Descriptions | G8: All | H8: Group Compliance Director | I8: 30 March 2026 | J8: As per Document Register defined review date, or upon significant change to role

Sheet General Documents
C1: Seagull Maritime — Document Register — General Documents
C2: SM/INT/REG/001 | DOC | MAN
A4: Document Reference | B4: Document Title | C4: System | D4: Version | E4: Status | F4: Folder Location | G4: ISO Standard(s) | H4: Document Owner | I4: Issue Date | J4: Next Review | K4: Legacy Reference | L4: Notes
A5: SM/INT/DOC/001 | B5: Document Referencing and Folder Structure Guide | C5: INT | D5: 1.0 | E5: Approved | F5: 00 - Management System Overview | G5: All | H5: Group Compliance Director | I5: 23/03/2026 | J5: 23/03/2027 | L5: First document in new referencing system
A6: SM/INT/DOC/002 | B6: Context of the Organisation (PESTLE & SWOT Analysis) | C6: INT | D6: 2.0 | E6: Approved | F6: 01 - Policies/Context of the Organisation | G6: ISO 45001 (4.1) | ISO 18788 (4.1) | ISO 28000 (4.1) | ISO 9001 (4.1) | H6: Group Compliance Director | I6: 01/03/2026 | J6: 01/03/2027 | L6: v1.0 pre-war baseline (Feb 2026). v2.0 Iran war emergency review (Mar 2026)
A7: SM/CAM/BUL/001 | B7: Vessel Transfers — Awareness Bulletin | C7: CAM | D7: 1.0 | E7: Approved | F7: 13 - Campaign / Bulletins | G7: N/A — Awareness material | H7: Group Compliance Director | I7: 31/03/2026 | J7: 31/03/2027 | L7: First campaign bulletin. Assess/Report/Deliver pillars. Hosted on GitHub Pages. Template for future bulletins.
A8: SM/CAM/FC/001 | B8: Vessel Transfers — Toolbox Talk Flash Cards | C8: CAM | D8: 1.0 | E8: Approved | F8: 13 - Campaign / Flash Cards | G8: N/A — Awareness material | H8: Group Compliance Director | I8: 31/03/2026 | J8: 31/03/2027 | L8: 6 printable cards (2x3 grid). PPE, Before/During/After Transfer, Key Hazards, Stop the Transfer. Hosted on GitHub Pages.
A9: SM/CAM/BRAG/002 | B9: Security Duties – Client Vessel — Basic Risk Assessment Guide | C9: CAM | D9: 1.0 | E9: Approved | F9: 13 - Campaign - Your Watch Our Standard/Basic Risk Assessment Guides | G9: ISO 45001 | H9: Group Compliance Director | I9: 31/03/2026 | J9: 31/03/2027 | K9: SM-CAM-BRAG-002 | L9: 14 hazards, 2-page guide for frontline security teams
A10: SM/CAM/BRAG/001 | B10: Vessel Transfer Operations — Basic Risk Assessment Guide | C10: CAM | D10: 1.0 | E10: Approved | F10: 13 - Campaign/Basic Risk Assessment Guides | G10: ISO 45001 | H10: Group Compliance Director | I10: 31/03/2026 | J10: 31/03/2027 | L10: 14 hazards condensed from RA-002. Plain-language 2-page guide for frontline workers.
A11: SM/CAM/BRAG/003 | B11: Weapons Handling and Armoury Operations — Basic Risk Assessment Guide | C11: CAM | D11: 1.0 | E11: Approved | F11: 13 - Campaign/Basic Risk Assessment Guides | G11: ISO 45001 | H11: Group Compliance Director | I11: 31/03/2026 | J11: 31/03/2027 | L11: 12 hazards condensed from RA-004. Plain-language guide.
A12: SM/CAM/BRAG/004 | B12: RHIB and Craft Launch Operations — Basic Risk Assessment Guide | C12: CAM | D12: 1.0 | E12: Approved | F12: 13 - Campaign/Basic Risk Assessment Guides | G12: ISO 45001 | H12: Group Compliance Director | I12: 31/03/2026 | J12: 31/03/2027 | L12: 12 hazards condensed from RA-005. Plain-language guide.
A13: SM/CAM/BRAG/005 | B13: Vessel Routine Operations — Basic Risk Assessment Guide | C13: CAM | D13: 1.0 | E13: Approved | F13: 13 - Campaign/Basic Risk Assessment Guides | G13: ISO 45001 | H13: Group Compliance Director | I13: 31/03/2026 | J13: 31/03/2027 | L13: 14 hazards condensed from RA-006. Plain-language guide.
A14: SM/CAM/BRAG/006 | B14: Office Workplace — Basic Risk Assessment Guide | C14: CAM | D14: 1.0 | E14: Approved | F14: 13 - Campaign/Basic Risk Assessment Guides | G14: ISO 45001 | H14: Group Compliance Director | I14: 31/03/2026 | J14: 31/03/2027 | L14: 12 hazards condensed from RA-007. Office personnel guide.
A15: SM/CAM/BRAG/007 | B15: Remote Working — Basic Risk Assessment Guide | C15: CAM | D15: 1.0 | E15: Approved | F15: 13 - Campaign/Basic Risk Assessment Guides | G15: ISO 45001 | H15: Group Compliance Director | I15: 31/03/2026 | J15: 31/03/2027 | L15: 10 hazards condensed from RA-008. Remote worker guide.
A16: SM/CAM/BRAG/008 | B16: Heat Stress — Basic Risk Assessment Guide | C16: CAM | D16: 1.0 | E16: Approved | F16: 13 - Campaign/Basic Risk Assessment Guides | G16: ISO 45001 | H16: Group Compliance Director | I16: 31/03/2026 | J16: 31/03/2027 | L16: 10 hazards condensed from RA-009. Simple language for international crew.
A17: SM/INT/DOC/003 | B17: Risk Screening Tool — Concept and Design Specification | C17: INT | D17: 1.0 | E17: Approved | F17: 01 - Policies | G17: ISO 45001 (6.1) / ISO 18788 (6.1) / ISO 28000 (6.1) | H17: Group Compliance Director
A18: SM/SEC/DOC/001 | B18: OCIMF PMSC Guidance Checklist — Completed Responses | C18: SEC | D18: 1.0 | E18: Approved | F18: 06 / Due Diligence Packs | G18: ISO 28007 (4.4.6) / ISO 18788 (A.4.3.2) | H18: Group Compliance Director | I18: 02/04/2026 | J18: 02/07/2026 | K18: Supersedes legacy Malta OCIMF checklist
A19: SM/INT/DOC/004 | B19: Company Profile 2026 | C19: INT | D19: 1.0 | E19: Approved | F19: 00 - Management System Overview | G19: All | H19: Group Compliance Director
A20: SM/INT/DOC/006 | B20: MSO Course Program | C20: INT | D20: 1.0 | E20: Approved | F20: 02 - Procedures and SOPs | G20: 28007 / 18788 | H20: Group Compliance Director
A21: SM/CAM/BUL/002 | B21: Due Diligence Portal — Internal Bulletin | C21: CAM | D21: 1.0 | E21: Approved | F21: 13 - Campaign | G21: All | H21: Group Compliance Director
A22: SM/CAM/SG/001 | B22: Vessel Transfer Operations Safety Guide | C22: CAM | D22: 1.0 | E22: Approved | F22: 13 - Campaign / Safety Guides | G22: 45001 | H22: Group Compliance Director
A501: SM/CAM/BRAG/009 | B501: Night Operations Basic Risk Assessment Guide | C501: CAM | D501: 1.0 | E501: Approved | F501: 03 - Risk Assessments/RA-003 Series (HS - ISO 45001) | G501: ISO 45001 (7.3) | H501: Group Compliance Director | I501: 01/04/2026 | J501: 01/10/2026 | L501: Plain-language 2-page guide. 10 hazards distilled from SM/HSE/RA/010.
A502: SM/TRG/DOC/001 | B502: Human Rights in Maritime Security Operations — PCASP Training | C502: TRG | D502: 1.0 | E502: Approved | F502: 13 - Campaign - Your Watch Our Standard | G502: ICoCA / VPSHR / 18788 / 28007 | H502: Group Compliance Director | I502: 03/04/2026 | J502: 03/10/2026 | L502: 28-slide PPT training course. 3-layer framework (UDHR/VPSHR/ICoCA). For PCASP deployed personnel.
A503: SM/TRG/DOC/002 | B503: Human Rights in Maritime Security Operations — Staff and Management Training | C503: TRG | D503: 1.0 | E503: Approved | F503: 13 - Campaign - Your Watch Our Standard | G503: ICoCA / VPSHR / 18788 / 28007 | H503: Group Compliance Director | I503: 03/04/2026 | J503: 03/10/2026 | L503: 28-slide PPT training course. Reframed for shore-based staff/management oversight perspective.
A504: SM/SEC/DOC/002 | B504: WAF OCIMF Due Diligence Checklist | C504: SEC | D504: 1.0 | E504: Approved | F504: 06 - Client and Commercial / Due Diligence Packs | G504: ISO 28007 (4.4.6) / OCIMF | H504: Group Compliance Director | I504: 04/04/2026 | J504: Annual | L504: S28 Word format (docx-js). 52 questions, 8 sections. Matches IOR DOC-001 5-column layout. PDF on WAF DD portal.
A505: SM/INT/DOC/005 | B505: Roles, Responsibilities and Authorities Matrix (RACI) | C505: INT | D505: 1.0 | E505: Approved | F505: 00 - Management System Overview | G505: 45001 (5.3) / 18788 (5.3) | H505: Group Compliance Director | I505: 08/04/2026 | J505: 08/04/2027

Sheet Legacy Mapping
A1: Legacy to New Reference Mapping
A3: Legacy Reference | B3: New Reference | C3: Document Title | D3: Migration Status | E3: Migration Trigger | F3: Notes
A4: SMS/SOP/IO/001 | B4: SM/OPS/SOP/001 | C4: Indian Ocean Piracy Operations SOP | D4: Pending | E4: Shell findings amendment | F4: Ref changes when SOP is amended
A5: SM SOP - PG | B5: SM/OPS/SOP/002 | C5: Persian Gulf Vessel Evacuation and Guarding SOP | D5: Pending | E5: Next amendment
A6: SM RA-003 | B6: SM/HSE/RA/001 | C6: Vessel Evacuation and Guarding H&S RA | D6: Mapped | E6: Already in new system | F6: RA-003 pattern retained
A7: SM RA-004 IOR | B7: SM/SEC/RA/001 | C7: IOR Piracy Operations Security & Business RA | D7: Mapped | E7: Already in new system | F7: RA-004 pattern retained
A8: SM RA-004 WAF | B8: SM/SEC/RA/002 | C8: WAF GOG Operations Security & Business RA | D8: Mapped | E8: Already in new system | F8: RA-004 pattern retained
A9: SM RA-004 PG | B9: SM/SEC/RA/003 | C9: PG Vessel Evacuation and Guarding Security & Business RA | D9: Mapped | E9: Already in new system | F9: RA-004 pattern retained
A10: SM PRO-SEV-RA-001 | B10: SM/OFF/PRO/001 | C10: SEV Critical Spares RA Procedure | D10: Mapped | E10: Already in new system
A11: SM RA-SEV MED4 001 | B11: SM/OFF/RA/001 | C11: Critical Spares RA - MV Mediator IV | D11: Mapped | E11: Already in new system
A12: SM-JD-QHSE Manager-06.03.2026 | B12: SM/INT/JD/001 | C12: QHSE Manager Job Description | D12: Mapped | E12: Already in new system
A13: MSP-A series | B13: TBD | C13: Legacy management system procedures (various) | D13: Pending | E13: Review and update cycle | F13: Map individually when amended
A14: MSP-B series | B14: TBD | C14: Legacy management system procedures (various) | D14: Pending | E14: Review and update cycle | F14: Map individually when amended
A15: MSP-A-01 / OHSP14 / SOP-1001 | B15: SM/PRO/DOC/001 | C15: Control of Documents | D15: Complete | E15: Session 11 rebuild | F15: Multiple legacy procs superseded

Sheet Archived
A1: Archived / Superseded Documents
A3: Document Reference | B3: Document Title | C3: Final Version | D3: Superseded By | E3: Archive Date | F3: Reason
A4: SM/SEC/RA/003 | B4: PG Vessel Evacuation and Guarding Security & Business RA | C4: SEC | D4: 1.0 | E4: Archived | F4: 03 / RA-004 Series | G4: 18788 / 28000 | H4: Group Compliance Director | I4: 2026 | J4: 2027 | K4: SM RA-004 PG | L4: PG operations never actioned. Files in Misc. Archived S28.

Sheet Sequence Tracker
A1: Document Sequence Tracker
A2: Next available sequence number per system/type combination
A4: System | B4: Type | C4: Next Sequence | D4: Last Document Created
A5: INT | B5: DOC | C5: 007 | D5: SM/INT/DOC/006 - MSO Course Program
A6: INT | B6: REG | C6: 11 | D6: SM/INT/REG/010
A7: INT | B7: CPP | C7: 002 | D7: SM/INT/CPP/001 - MV Vladimir Boarding CPP
A8: INT | B8: SOW | C8: 002 | D8: SM/INT/SOW/001 - MV Vladimir SOW
A9: INT | B9: TPL | C9: 003 | D9: SM/INT/TPL/002 - Procedure Template
A10: INT | B10: JD | C10: 005 | D10: SM/INT/JD/004 - Group Compliance Director JD
A11: SEC | B11: RA | C11: 004 | D11: SM/SEC/RA/002 - WAF GOG Operations Security RA (003 PG Archived)
A12: SEC | B12: PRO | C12: 006 | D12: SM/SEC/PRO/005 - Supplier Approval SEV Providers
A13: HSE | B13: RA | C13: 011 | D13: SM/HSE/RA/010 - Night Operations H&S RA
A14: OPS | B14: SOP | C14: 003 | D14: SM/OPS/SOP/002 - WAF SEV Operations
A15: OFF | B15: PRO | C15: 002 | D15: SM/OFF/PRO/001 - SEV Critical Spares Procedure
A16: OFF | B16: RA | C16: 002 | D16: SM/OFF/RA/001 - Critical Spares RA Mediator IV
A17: INT | B17: RPT | C17: 002 | D17: SM/INT/RPT/001 - IA Programme Review
A18: INT | B18: CMP | C18: 003 | D18: SM/INT/CMP/002 - Combined Work Programme
... A20: INT | B20: PRO | C20: 022 | D20: SM/INT/PRO/021 - D&A Testing Procedure
A21: INT | B21: FORM | C21: 7 | D21: SM/INT/FORM/006
A22: HSE | B22: DOC | C22: 002 | D22: SM/HSE/DOC/001 - OH&S Scope Statement
A23: HSE | B23: POL | C23: 003 | D23: SM/HSE/POL/002 - Environmental Policy
A24: HSE | B24: REG | C24: 003 | D24: SM/HSE/REG/002 - Legal and Regulatory Requirements Register
A25: HSE | B25: PRO | C25: 004 | D25: SM/HSE/PRO/003 - Emergency Preparedness and Response
A26: CAM | B26: BUL | C26: 003 | D26: SM/CAM/BUL/002 - DD Portal Bulletin
A27: CAM | B27: FC | C27: 002 | D27: SM/CAM/FC/001 - Vessel Transfers Toolbox Talk Flash Cards
A28: CAM | B28: BRAG | C28: 010 | D28: SM/CAM/BRAG/009 - Night Operations BRAG
A29: SEC | B29: REG | C29: 002 | D29: SM/SEC/REG/001 - Flag State Requirements Register
A30: SEC | B30: DOC | C30: 003 | D30: SM/SEC/DOC/002 - WAF OCIMF Due Diligence Checklist
A31: OPS | B31: PRO | C31: 002 | D31: SM/OPS/PRO/001 - Rules on the Use of Force (legacy, see SEC/PRO/003)
A32: CAM | B32: SG | C32: 002 | D32: SM/CAM/SG/001 - Vessel Transfer Operations Safety Guide
A33: OPS | B33: SOP-ANN | C33: H | D33: SM/OPS/SOP/001-H - Disembarkation and Post Transit
A34: TRG | B34: DOC | C34: 003 | D34: SM/TRG/DOC/002 - Staff and Management Training
A35: SEC | B35: FORM | C35: 5 | D35: SM/SEC/FORM/004
A36: OPS | B36: FORM | C36: 018 | D36: SM/OPS/FORM/017 - Vessel Details Form
A37: INT | B37: POL | C37: 011 | D37: SM/INT/POL/010 - Drugs and Alcohol Policy
A38: HSE | B38: RPT | C38: 002 | D38: SM/HSE/RPT/001 - IRT Exercise Report
